WARNING  selenium.webdriver.common.selenium_manager:selenium_manager.py:138 Error sending stats to Plausible: error sending request for url (https://plausible.io/api/event)
WARNING  urllib3.connectionpool:connectionpool.py:870 Retrying (Retry(total=2, connect=None, read=None, redirect=None, status=None)) after connection broken by 'NewConnectionError('<urllib3.connection.HTTPConnection object at 0x0000024DE084AD10>: Failed to establish a new connection: [WinError 10061] No connection could be made because the target machine actively refused it')': /session/9700bc25c170c4b5d59ffd18168e5a58
WARNING  urllib3.connectionpool:connectionpool.py:870 Retrying (Retry(total=1, connect=None, read=None, redirect=None, status=None)) after connection broken by 'NewConnectionError('<urllib3.connection.HTTPConnection object at 0x0000024DE0875050>: Failed to establish a new connection: [WinError 10061] No connection could be made because the target machine actively refused it')': /session/9700bc25c170c4b5d59ffd18168e5a58
WARNING  urllib3.connectionpool:connectionpool.py:870 Retrying (Retry(total=0, connect=None, read=None, redirect=None, status=None)) after connection broken by 'NewConnectionError('<urllib3.connection.HTTPConnection object at 0x0000024DE0876B90>: Failed to establish a new connection: [WinError 10061] No connection could be made because the target machine actively refused it')': /session/9700bc25c170c4b5d59ffd18168e5a58