{"name": "test_login[creds1]", "status": "failed", "statusDetails": {"message": "AssertionError: Test failed due to: list index out of range\nassert False", "trace": "self = <TDD.pageobject.test_login.DemoPOM object at 0x000001EFBDB3D2D0>\ndriver = <selenium.webdriver.chrome.webdriver.WebDriver (session=\"4d36c4a8cb536a9d96c20a7c6ac492a5\")>\ncreds = []\n\n    def verify_login(self,driver,creds):\n        try:\n            link = driver.find_element(By.XPATH, DemoPOM.login_xpath).click()\n>           driver.find_element(By.ID, \"Email\").send_keys(creds[0])\nE           IndexError: list index out of range\n\n..\\pageobject\\test_login.py:17: IndexError\n\nDuring handling of the above exception, another exception occurred:\n\nself = <test_testcase.Test_Case object at 0x000001EFBE4D8890>\ndriver = <selenium.webdriver.chrome.webdriver.WebDriver (session=\"4d36c4a8cb536a9d96c20a7c6ac492a5\")>\ncreds = []\n\n    @pytest.mark.m1\n    @pytest.mark.parametrize(\"creds\",helper.user_list())\n    def test_login(self,driver,creds):\n        helper.open_browser(driver)\n>       demo.verify_login(driver,creds)\n\ntest_testcase.py:14: \n_ _ _ _ _ _ _ _ _ _ _ _ _ _ _ _ _ _ _ _ _ _ _ _ _ _ _ _ _ _ _ _ _ _ _ _ _ _ _ _\n\nself = <TDD.pageobject.test_login.DemoPOM object at 0x000001EFBDB3D2D0>\ndriver = <selenium.webdriver.chrome.webdriver.WebDriver (session=\"4d36c4a8cb536a9d96c20a7c6ac492a5\")>\ncreds = []\n\n    def verify_login(self,driver,creds):\n        try:\n            link = driver.find_element(By.XPATH, DemoPOM.login_xpath).click()\n            driver.find_element(By.ID, \"Email\").send_keys(creds[0])\n            driver.find_element(By.ID, \"Password\").send_keys(creds[1])\n            driver.find_element(By.XPATH, \"//*[@value='Log in']\").click()\n            time.sleep(3)\n        except Exception as e:\n            helper.record_error(driver, e)\n>           assert False, f\"Test failed due to: {str(e)}\"\nE           AssertionError: Test failed due to: list index out of range\nE           assert False\n\n..\\pageobject\\test_login.py:23: AssertionError"}, "attachments": [{"name": "stdout", "source": "ab001f5f-8a09-4f78-9d44-262cb26905ec-attachment.txt", "type": "text/plain"}], "parameters": [{"name": "creds", "value": "[]"}], "start": 1741064591923, "stop": 1741064605450, "uuid": "fe072906-e1c7-4dc5-952d-d2f273e8d8a8", "historyId": "0f8b4c8902c339b27c955a70ee76e591", "testCaseId": "a605e4e099a5192c43621ae00228d983", "fullName": "test_testcase.Test_Case#test_login", "labels": [{"name": "tag", "value": "m1"}, {"name": "suite", "value": "test_testcase"}, {"name": "subSuite", "value": "Test_Case"}, {"name": "host", "value": "LAPTOP-U3Q4N1TL"}, {"name": "thread", "value": "9644-MainThread"}, {"name": "framework", "value": "pytest"}, {"name": "language", "value": "cpython3"}, {"name": "package", "value": "test_testcase"}]}