WARNING  selenium.webdriver.common.selenium_manager:selenium_manager.py:138 Error sending stats to Plausible: error sending request for url (https://plausible.io/api/event)
WARNING  urllib3.connectionpool:connectionpool.py:870 Retrying (Retry(total=2, connect=None, read=None, redirect=None, status=None)) after connection broken by 'NewConnectionError('<urllib3.connection.HTTPConnection object at 0x0000024A85CBA450>: Failed to establish a new connection: [WinError 10061] No connection could be made because the target machine actively refused it')': /session/5f53651b5cc55229ae5aa69cd114ae34
WARNING  urllib3.connectionpool:connectionpool.py:870 Retrying (Retry(total=1, connect=None, read=None, redirect=None, status=None)) after connection broken by 'NewConnectionError('<urllib3.connection.HTTPConnection object at 0x0000024A85CBA650>: Failed to establish a new connection: [WinError 10061] No connection could be made because the target machine actively refused it')': /session/5f53651b5cc55229ae5aa69cd114ae34
WARNING  urllib3.connectionpool:connectionpool.py:870 Retrying (Retry(total=0, connect=None, read=None, redirect=None, status=None)) after connection broken by 'NewConnectionError('<urllib3.connection.HTTPConnection object at 0x0000024A85CBAD90>: Failed to establish a new connection: [WinError 10061] No connection could be made because the target machine actively refused it')': /session/5f53651b5cc55229ae5aa69cd114ae34